Workbook
Name Slicer_Department: #N/A
Name Slicer_EducationField: #N/A
Name Slicer_Gender: #N/A
Name Slicer_OverTime: #N/A
Name Slicer_Risk_Category: #N/A

Sheet Dashboard
A1: HR Predictive Attrition Analytics & BI Dashboard
Q3: =GETPIVOTDATA("Count of EmployeeID",Pivot_Engine!$A$34) -> 1470 | AF3: =GETPIVOTDATA("Average of Attrition",Pivot_Engine!$A$34) -> 0.16122449 | AQ3: =GETPIVOTDATA("Average of Attrition_Risk_Percentage",Pivot_Engine!$A$1) -> 0.3233582 | BD3: =SUM(Pivot_Engine!J8:J9) -> 114 | BM3: =GETPIVOTDATA("IncomeAtRisk",Pivot_Engine!$A$47) -> 1497031.5 | BO3: =GETPIVOTDATA("Average of MonthlyIncome",Pivot_Engine!$A$34) -> 6502.9313
R4: =GETPIVOTDATA("Count of EmployeeID",Pivot_Engine!$A$34,"Gender","Male") -> 882 | V4: =GETPIVOTDATA("Count of EmployeeID",Pivot_Engine!$A$34,"Gender","Female") -> 588
BM6: Top High Risk Employees
W7: Attrition by Department | AY7: Risk Breakdown | BM7: Employee ID | BN7: Job Role | BO7: Risk (%) | BP7: Perfomance★
BM8: =Pivot_Engine!I34 -> EMP-100258 | BN8: =Pivot_Engine!J34 -> Research Scientist | BO8: =Pivot_Engine!K34 -> 0.85514327 | BP8: =REPT("★",Pivot_Engine!L34) & REPT("☆",4-Pivot_Engine!L34) -> ★★★☆
BM9: =Pivot_Engine!I35 -> EMP-100284 | BN9: =Pivot_Engine!J35 -> Laboratory Technician | BO9: =Pivot_Engine!K35 -> 0.8222116 | BP9: =REPT("★",Pivot_Engine!L35) & REPT("☆",4-Pivot_Engine!L35) -> ★★★☆
BM10: =Pivot_Engine!I36 -> EMP-100363 | BN10: =Pivot_Engine!J36 -> Research Scientist | BO10: =Pivot_Engine!K36 -> 0.8222116 | BP10: =REPT("★",Pivot_Engine!L36) & REPT("☆",4-Pivot_Engine!L36) -> ★★★☆
BM11: =Pivot_Engine!I37 -> EMP-100462 | BN11: =Pivot_Engine!J37 -> Manufacturing Director | BO11: =Pivot_Engine!K37 -> 0.8222116 | BP11: =REPT("★",Pivot_Engine!L37) & REPT("☆",4-Pivot_Engine!L37) -> ★★★☆
BM12: =Pivot_Engine!I38 -> EMP-100673 | BN12: =Pivot_Engine!J38 -> Healthcare Representative | BO12: =Pivot_Engine!K38 -> 0.89091967 | BP12: =REPT("★",Pivot_Engine!L38) & REPT("☆",4-Pivot_Engine!L38) -> ★★★☆
BM13: =Pivot_Engine!I39 -> EMP-100713 | BN13: =Pivot_Engine!J39 -> Research Scientist | BO13: =Pivot_Engine!K39 -> 0.8222116 | BP13: =REPT("★",Pivot_Engine!L39) & REPT("☆",4-Pivot_Engine!L39) -> ★★★☆
BM14: =Pivot_Engine!I40 -> EMP-100760 | BN14: =Pivot_Engine!J40 -> Laboratory Technician | BO14: =Pivot_Engine!K40 -> 0.8222116 | BP14: =REPT("★",Pivot_Engine!L40) & REPT("☆",4-Pivot_Engine!L40) -> ★★★☆
Y21: Risk by Tenure | BL21: Risk by Monthly Income

Sheet HR
A1: EmployeeID | B1: Age | C1: BusinessTravel | D1: DailyRate | E1: Department | F1: DistanceFromHome | G1: Education | H1: EducationField | I1: EnvironmentSatisfaction | J1: Gender | K1: HourlyRate | L1: JobInvolvement | M1: JobLevel | N1: JobRole | O1: JobSatisfaction | P1: MaritalStatus | Q1: MonthlyIncome | R1: MonthlyRate | S1: NumCompaniesWorked | T1: OverTime | U1: PercentSalaryHike | V1: PerformanceRating | W1: RelationshipSatisfaction | X1: StockOptionLevel | Y1: TotalWorkingYears | Z1: TrainingTimesLastYear | AA1: WorkLifeBalance | AB1: YearsAtCompany | AC1: YearsInCurrentRole | AD1: YearsSinceLastPromotion | AE1: YearsWithCurrManager | AF1: Attrition | AG1: Gender_Code | AH1: Travel_Code | AI1: Marital_Code | AJ1: Flag_OT | AK1: Flag_Distance | AL1: Flag_Satisfaction | AM1: Flag_Income | AN1: Flag_Travel | AO1: Risk_Score_Raw | AP1: Attrition_Risk_Percentage | AQ1: Risk_Category | AR1: IncomeAtRisk
A2: EMP-100844 | B2: 41 | C2: Travel_Rarely | D2: 1102 | E2: Sales | F2: 1 | G2: 2 | H2: Life Sciences | I2: 2 | J2: Female | K2: 94 | L2: 3 | M2: 2 | N2: Sales Executive | O2: 4 | P2: Single | Q2: 5993 | R2: 19479 | S2: 8 | T2: 1 | U2: 0.11 | V2: 3 | W2: 1 | X2: 0 | Y2: 8 | Z2: 0 | AA2: 1 | AB2: 6 | AC2: 4 | AD2: 0 | AE2: 5 | AF2: 1 | AG2: =IF(tbl_HR_Data[[#This Row],[Gender]]="Male",1,0) -> 0 | AH2: {=_xlfn.SWITCH(tbl_HR_Data[[#This Row],[BusinessTravel]], "Non-Travel", 0, "Travel_Rarely", 1, "Travel_Frequently", 2)} -> 1 | AI2: {=_xlfn.SWITCH(tbl_HR_Data[[#This Row],[MaritalStatus]],"Single",0,"Married",1,"Divorced",2)} -> 0 | AJ2: =IF(tbl_HR_Data[[#This Row],[OverTime]]=1,1,0) -> 1 | AK2: =IF(tbl_HR_Data[[#This Row],[DistanceFromHome]]>15,1,0) -> 0 | AL2: =IF(tbl_HR_Data[[#This Row],[JobSatisfaction]]<=2,1,0) -> 0 | AM2: =IF(tbl_HR_Data[[#This Row],[MonthlyIncome]]<$AT$2,1,0) -> 0 | AN2: =IF(tbl_HR_Data[[#This Row],[Travel_Code]]=2,1,0) -> 0 | AO2: =(tbl_HR_Data[[#This Row],[Flag_OT]] * Logic_Parameters!$B$2) + (tbl_HR_Data[[#This Row],[Flag_Travel]] * Logic_Parameters!$B$3) + (tbl_HR_Data[[#This Row],[Flag_Satisfaction]] * Logic_Parameters!$B$4) + (tbl_HR_Data[[#This Row],[Flag_Distance]]* Logic_Parameters!$B$5) + (tbl_HR_Data[[#This Row],[Flag_Income]] * Logic_Parameters!$B$6) -> 10 | AP2: =tbl_HR_Data[[#This Row],[Risk_Score_Raw]] / SUM(Logic_Parameters!$B$2:$B$6) -> 0.34452513 | AQ2: {=_xlfn.IFS(tbl_HR_Data[[#This Row],[Attrition_Risk_Percentage]] >= 0.75, "Critical",tbl_HR_Data[ [#This Row],[Attrition_Risk_Percentage] ]>= 0.5, "High",tbl_HR_Data[[#This Row],[Attrition_Risk_Percentage]] >= 0.25, "Medium",TRUE, "Low")} -> Medium | AR2: {=IFERROR(_xlfn.IFS(tbl_HR_Data[[#This Row],[Risk_Category]]="Critical",tbl_HR_Data[[#This Row],[MonthlyIncome]]*1.5,tbl_HR_Data[[#This Row],[Risk_Category]]="High",tbl_HR_Data[[#This Row],[MonthlyIncome]]*1.5),0)} -> 0 | AS2: Median income | AT2: =MEDIAN(tbl_HR_Data[MonthlyIncome]) -> 4919
A3: EMP-100039 | B3: 49 | C3: Travel_Frequently | D3: 279 | E3: Research & Development | F3: 8 | G3: 1 | H3: Life Sciences | I3: 3 | J3: Male | K3: 61 | L3: 2 | M3: 2 | N3: Research Scientist | O3: 2 | P3: Married | Q3: 5130 | R3: 24907 | S3: 1 | T3: 0 | U3: 0.23 | V3: 4 | W3: 4 | X3: 1 | Y3: 10 | Z3: 3 | AA3: 3 | AB3: 10 | AC3: 7 | AD3: 1 | AE3: 7 | AF3: 0 | AG3: =IF(tbl_HR_Data[[#This Row],[Gender]]="Male",1,0) -> 1 | AH3: {=_xlfn.SWITCH(tbl_HR_Data[[#This Row],[BusinessTravel]], "Non-Travel", 0, "Travel_Rarely", 1, "Travel_Frequently", 2)} -> 2 | AI3: {=_xlfn.SWITCH(tbl_HR_Data[[#This Row],[MaritalStatus]],"Single",0,"Married",1,"Divorced",2)} -> 1 | AJ3: =IF(tbl_HR_Data[[#This Row],[OverTime]]=1,1,0) -> 0 | AK3: =IF(tbl_HR_Data[[#This Row],[DistanceFromHome]]>15,1,0) -> 0 | AL3: =IF(tbl_HR_Data[[#This Row],[JobSatisfaction]]<=2,1,0) -> 1 | AM3: =IF(tbl_HR_Data[[#This Row],[MonthlyIncome]]<$AT$2,1,0) -> 0 | AN3: =IF(tbl_HR_Data[[#This Row],[Travel_Code]]=2,1,0) -> 1 | AO3: =(tbl_HR_Data[[#This Row],[Flag_OT]] * Logic_Parameters!$B$2) + (tbl_HR_Data[[#This Row],[Flag_Travel]] * Logic_Parameters!$B$3) + (tbl_HR_Data[[#This Row],[Flag_Satisfaction]] * Logic_Parameters!$B$4) + (tbl_HR_Data[[#This Row],[Flag_Distance]]* Logic_Parameters!$B$5) + (tbl_HR_Data[[#This Row],[Flag_Income]] * Logic_Parameters!$B$6) -> 9.3649231 | AP3: =tbl_HR_Data[[#This Row],[Risk_Score_Raw]] / SUM(Logic_Parameters!$B$2:$B$6) -> 0.32264514 | AQ3: {=_xlfn.IFS(tbl_HR_Data[[#This Row],[Attrition_Risk_Percentage]] >= 0.75, "Critical",tbl_HR_Data[ [#This Row],[Attrition_Risk_Percentage] ]>= 0.5, "High",tbl_HR_Data[[#This Row],[Attrition_Risk_Percentage]] >= 0.25, "Medium",TRUE, "Low")} -> Medium | AR3: {=IFERROR(_xlfn.IFS(tbl_HR_Data[[#This Row],[Risk_Category]]="Critical",tbl_HR_Data[[#This Row],[MonthlyIncome]]*1.5,tbl_HR_Data[[#This Row],[Risk_Category]]="High",tbl_HR_Data[[#This Row],[MonthlyIncome]]*1.5),0)} -> 0
A4: EMP-100022 | B4: 37 | C4: Travel_Rarely | D4: 1373 | E4: Research & Development | F4: 2 | G4: 2 | H4: Other | I4: 4 | J4: Male | K4: 92 | L4: 2 | M4: 1 | N4: Laboratory Technician | O4: 3 | P4: Single | Q4: 2090 | R4: 2396 | S4: 6 | T4: 1 | U4: 0.15 | V4: 3 | W4: 2 | X4: 0 | Y4: 7 | Z4: 3 | AA4: 3 | AB4: 0 | AC4: 0 | AD4: 0 | AE4: 0 | AF4: 1 | AG4: =IF(tbl_HR_Data[[#This Row],[Gender]]="Male",1,0) -> 1 | AH4: {=_xlfn.SWITCH(tbl_HR_Data[[#This Row],[BusinessTravel]], "Non-Travel", 0, "Travel_Rarely", 1, "Travel_Frequently", 2)} -> 1 | AI4: {=_xlfn.SWITCH(tbl_HR_Data[[#This Row],[MaritalStatus]],"Single",0,"Married",1,"Divorced",2)} -> 0 | AJ4: =IF(tbl_HR_Data[[#This Row],[OverTime]]=1,1,0) -> 1 | AK4: =IF(tbl_HR_Data[[#This Row],[DistanceFromHome]]>15,1,0) -> 0 | AL4: =IF(tbl_HR_Data[[#This Row],[JobSatisfaction]]<=2,1,0) -> 0 | AM4: =IF(tbl_HR_Data[[#This Row],[MonthlyIncome]]<$AT$2,1,0) -> 1 | AN4: =IF(tbl_HR_Data[[#This Row],[Travel_Code]]=2,1,0) -> 0 | AO4: =(tbl_HR_Data[[#This Row],[Flag_OT]] * Logic_Parameters!$B$2) + (tbl_HR_Data[[#This Row],[Flag_Travel]] * Logic_Parameters!$B$3) + (tbl_HR_Data[[#This Row],[Flag_Satisfaction]] * Logic_Parameters!$B$4) + (tbl_HR_Data[[#This Row],[Flag_Distance]]* Logic_Parameters!$B$5) + (tbl_HR_Data[[#This Row],[Flag_Income]] * Logic_Parameters!$B$6) -> 16.494429 | AP4: =tbl_HR_Data[[#This Row],[Risk_Score_Raw]] / SUM(Logic_Parameters!$B$2:$B$6) -> 0.56827453 | AQ4: {=_xlfn.IFS(tbl_HR_Data[[#This Row],[Attrition_Risk_Percentage]] >= 0.75, "Critical",tbl_HR_Data[ [#This Row],[Attrition_Risk_Percentage] ]>= 0.5, "High",tbl_HR_Data[[#This Row],[Attrition_Risk_Percentage]] >= 0.25, "Medium",TRUE, "Low")} -> High | AR4: {=IFERROR(_xlfn.IFS(tbl_HR_Data[[#This Row],[Risk_Category]]="Critical",tbl_HR_Data[[#This Row],[MonthlyIncome]]*1.5,tbl_HR_Data[[#This Row],[Risk_Category]]="High",tbl_HR_Data[[#This Row],[MonthlyIncome]]*1.5),0)} -> 3135
A5: EMP-100661 | B5: 33 | C5: Travel_Frequently | D5: 1392 | E5: Research & Development | F5: 3 | G5: 4 | H5: Life Sciences | I5: 4 | J5: Female | K5: 56 | L5: 3 | M5: 1 | N5: Research Scientist | O5: 3 | P5: Married | Q5: 2909 | R5: 23159 | S5: 1 | T5: 1 | U5: 0.11 | V5: 3 | W5: 3 | X5: 0 | Y5: 8 | Z5: 3 | AA5: 3 | AB5: 8 | AC5: 7 | AD5: 3 | AE5: 0 | AF5: 0 | AG5: =IF(tbl_HR_Data[[#This Row],[Gender]]="Male",1,0) -> 0 | AH5: {=_xlfn.SWITCH(tbl_HR_Data[[#This Row],[BusinessTravel]], "Non-Travel", 0, "Travel_Rarely", 1, "Travel_Frequently", 2)} -> 2 | AI5: {=_xlfn.SWITCH(tbl_HR_Data[[#This Row],[MaritalStatus]],"Single",0,"Married",1,"Divorced",2)} -> 1 | AJ5: =IF(tbl_HR_Data[[#This Row],[OverTime]]=1,1,0) -> 1 | AK5: =IF(tbl_HR_Data[[#This Row],[DistanceFromHome]]>15,1,0) -> 0 | AL5: =IF(tbl_HR_Data[[#This Row],[JobSatisfaction]]<=2,1,0) -> 0 | AM5: =IF(tbl_HR_Data[[#This Row],[MonthlyIncome]]<$AT$2,1,0) -> 1 | AN5: =IF(tbl_HR_Data[[#This Row],[Travel_Code]]=2,1,0) -> 1 | AO5: =(tbl_HR_Data[[#This Row],[Flag_OT]] * Logic_Parameters!$B$2) + (tbl_HR_Data[[#This Row],[Flag_Travel]] * Logic_Parameters!$B$3) + (tbl_HR_Data[[#This Row],[Flag_Satisfaction]] * Logic_Parameters!$B$4) + (tbl_HR_Data[[#This Row],[Flag_Distance]]* Logic_Parameters!$B$5) + (tbl_HR_Data[[#This Row],[Flag_Income]] * Logic_Parameters!$B$6) -> 21.654819 | AP5: =tbl_HR_Data[[#This Row],[Risk_Score_Raw]] / SUM(Logic_Parameters!$B$2:$B$6) -> 0.74606293 | AQ5: {=_xlfn.IFS(tbl_HR_Data[[#This Row],[Attrition_Risk_Percentage]] >= 0.75, "Critical",tbl_HR_Data[ [#This Row],[Attrition_Risk_Percentage] ]>= 0.5, "High",tbl_HR_Data[[#This Row],[Attrition_Risk_Percentage]] >= 0.25, "Medium",TRUE, "Low")} -> High | AR5: {=IFERROR(_xlfn.IFS(tbl_HR_Data[[#This Row],[Risk_Category]]="Critical",tbl_HR_Data[[#This Row],[MonthlyIncome]]*1.5,tbl_HR_Data[[#This Row],[Risk_Category]]="High",tbl_HR_Data[[#This Row],[MonthlyIncome]]*1.5),0)} -> 4363.5
A6: EMP-100474 | B6: 27 | C6: Travel_Rarely | D6: 591 | E6: Research & Development | F6: 2 | G6: 1 | H6: Medical | I6: 1 | J6: Male | K6: 40 | L6: 3 | M6: 1 | N6: Laboratory Technician | O6: 2 | P6: Married | Q6: 3468 | R6: 16632 | S6: 9 | T6: 0 | U6: 0.12 | V6: 3 | W6: 4 | X6: 1 | Y6: 6 | Z6: 3 | AA6: 3 | AB6: 2 | AC6: 2 | AD6: 2 | AE6: 2 | AF6: 0 | AG6: =IF(tbl_HR_Data[[#This Row],[Gender]]="Male",1,0) -> 1 | AH6: {=_xlfn.SWITCH(tbl_HR_Data[[#This Row],[BusinessTravel]], "Non-Travel", 0, "Travel_Rarely", 1, "Travel_Frequently", 2)} -> 1 | AI6: {=_xlfn.SWITCH(tbl_HR_Data[[#This Row],[MaritalStatus]],"Single",0,"Married",1,"Divorced",2)} -> 1 | AJ6: =IF(tbl_HR_Data[[#This Row],[OverTime]]=1,1,0) -> 0 | AK6: =IF(tbl_HR_Data[[#This Row],[DistanceFromHome]]>15,1,0) -> 0 | AL6: =IF(tbl_HR_Data[[#This Row],[JobSatisfaction]]<=2,1,0) -> 1 | AM6: =IF(tbl_HR_Data[[#This Row],[MonthlyIncome]]<$AT$2,1,0) -> 1 | AN6: =IF(tbl_HR_Data[[#This Row],[Travel_Code]]=2,1,0) -> 0 | AO6: =(tbl_HR_Data[[#This Row],[Flag_OT]] * Logic_Parameters!$B$2) + (tbl_HR_Data[[#This Row],[Flag_Travel]] * Logic_Parameters!$B$3) + (tbl_HR_Data[[#This Row],[Flag_Satisfaction]] * Logic_Parameters!$B$4) + (tbl_HR_Data[[#This Row],[Flag_Distance]]* Logic_Parameters!$B$5) + (tbl_HR_Data[[#This Row],[Flag_Income]] * Logic_Parameters!$B$6) -> 10.698962 | AP6: =tbl_HR_Data[[#This Row],[Risk_Score_Raw]] / SUM(Logic_Parameters!$B$2:$B$6) -> 0.36860613 | AQ6: {=_xlfn.IFS(tbl_HR_Data[[#This Row],[Attrition_Risk_Percentage]] >= 0.75, "Critical",tbl_HR_Data[ [#This Row],[Attrition_Risk_Percentage] ]>= 0.5, "High",tbl_HR_Data[[#This Row],[Attrition_Risk_Percentage]] >= 0.25, "Medium",TRUE, "Low")} -> Medium | AR6: {=IFERROR(_xlfn.IFS(tbl_HR_Data[[#This Row],[Risk_Category]]="Critical",tbl_HR_Data[[#This Row],[MonthlyIncome]]*1.5,tbl_HR_Data[[#This Row],[Risk_Category]]="High",tbl_HR_Data[[#This Row],[MonthlyIncome]]*1.5),0)} -> 0
A7: EMP-101433 | B7: 32 | C7: Travel_Frequently | D7: 1005 | E7: Research & Development | F7: 2 | G7: 2 | H7: Life Sciences | I7: 4 | J7: Male | K7: 79 | L7: 3 | M7: 1 | N7: Laboratory Technician | O7: 4 | P7: Single | Q7: 3068 | R7: 11864 | S7: 0 | T7: 0 | U7: 0.13 | V7: 3 | W7: 3 | X7: 0 | Y7: 8 | Z7: 2 | AA7: 2 | AB7: 7 | AC7: 7 | AD7: 3 | AE7: 6 | AF7: 0 | AG7: =IF(tbl_HR_Data[[#This Row],[Gender]]="Male",1,0) -> 1 | AH7: {=_xlfn.SWITCH(tbl_HR_Data[[#This Row],[BusinessTravel]], "Non-Travel", 0, "Travel_Rarely", 1, "Travel_Frequently", 2)} -> 2 | AI7: {=_xlfn.SWITCH(tbl_HR_Data[[#This Row],[MaritalStatus]],"Single",0,"Married",1,"Divorced",2)} -> 0 | AJ7: =IF(tbl_HR_Data[[#This Row],[OverTime]]=1,1,0) -> 0 | AK7: =IF(tbl_HR_Data[[#This Row],[DistanceFromHome]]>15,1,0) -> 0 | AL7: =IF(tbl_HR_Data[[#This Row],[JobSatisfaction]]<=2,1,0) -> 0 | AM7: =IF(tbl_HR_Data[[#This Row],[MonthlyIncome]]<$AT$2,1,0) -> 1 | AN7: =IF(tbl_HR_Data[[#This Row],[Travel_Code]]=2,1,0) -> 1 | AO7: =(tbl_HR_Data[[#This Row],[Flag_OT]] * Logic_Parameters!$B$2) + (tbl_HR_Data[[#This Row],[Flag_Travel]] * Logic_Parameters!$B$3) + (tbl_HR_Data[[#This Row],[Flag_Satisfaction]] * Logic_Parameters!$B$4) + (tbl_HR_Data[[#This Row],[Flag_Distance]]* Logic_Parameters!$B$5) + (tbl_HR_Data[[#This Row],[Flag_Income]] * Logic_Parameters!$B$6) -> 11.654819 | AP7: =tbl_HR_Data[[#This Row],[Risk_Score_Raw]] / SUM(Logic_Parameters!$B$2:$B$6) -> 0.4015378 | AQ7: {=_xlfn.IFS(tbl_HR_Data[[#This Row],[Attrition_Risk_Percentage]] >= 0.75, "Critical",tbl_HR_Data[ [#This Row],[Attrition_Risk_Percentage] ]>= 0.5, "High",tbl_HR_Data[[#This Row],[Attrition_Risk_Percentage]] >= 0.25, "Medium",TRUE, "Low")} -> Medium | AR7: {=IFERROR(_xlfn.IFS(tbl_HR_Data[[#This Row],[Risk_Category]]="Critical",tbl_HR_Data[[#This Row],[MonthlyIncome]]*1.5,tbl_HR_Data[[#This Row],[Risk_Category]]="High",tbl_HR_Data[[#This Row],[MonthlyIncome]]*1.5),0)} -> 0
A8: EMP-101255 | B8: 59 | C8: Travel_Rarely | D8: 1324 | E8: Research & Development | F8: 3 | G8: 3 | H8: Medical | I8: 3 | J8: Female | K8: 81 | L8: 4 | M8: 1 | N8: Laboratory Technician | O8: 1 | P8: Married | Q8: 2670 | R8: 9964 | S8: 4 | T8: 1 | U8: 0.2 | V8: 4 | W8: 1 | X8: 3 | Y8: 12 | Z8: 3 | AA8: 2 | AB8: 1 | AC8: 0 | AD8: 0 | AE8: 0 | AF8: 0 | AG8: =IF(tbl_HR_Data[[#This Row],[Gender]]="Male",1,0) -> 0 | AH8: {=_xlfn.SWITCH(tbl_HR_Data[[#This Row],[BusinessTravel]], "Non-Travel", 0, "Travel_Rarely", 1, "Travel_Frequently", 2)} -> 1 | AI8: {=_xlfn.SWITCH(tbl_HR_Data[[#This Row],[MaritalStatus]],"Single",0,"Married",1,"Divorced",2)} -> 1 | AJ8: =IF(tbl_HR_Data[[#This Row],[OverTime]]=1,1,0) -> 1 | AK8: =IF(tbl_HR_Data[[#This Row],[DistanceFromHome]]>15,1,0) -> 0 | AL8: =IF(tbl_HR_Data[[#This Row],[JobSatisfaction]]<=2,1,0) -> 1 | AM8: =IF(tbl_HR_Data[[#This Row],[MonthlyIncome]]<$AT$2,1,0) -> 1 | AN8: =IF(tbl_HR_Data[[#This Row],[Travel_Code]]=2,1,0) -> 0 | AO8: =(tbl_HR_Data[[#This Row],[Flag_OT]] * Logic_Parameters!$B$2) + (tbl_HR_Data[[#This Row],[Flag_Travel]] * Logic_Parameters!$B$3) + (tbl_HR_Data[[#This Row],[Flag_Satisfaction]] * Logic_Parameters!$B$4) + (tbl_HR_Data[[#This Row],[Flag_Distance]]* Logic_Parameters!$B$5) + (tbl_HR_Data[[#This Row],[Flag_Income]] * Logic_Parameters!$B$6) -> 20.698962 | AP8: =tbl_HR_Data[[#This Row],[Risk_Score_Raw]] / SUM(Logic_Parameters!$B$2:$B$6) -> 0.71313126 | AQ8: {=_xlfn.IFS(tbl_HR_Data[[#This Row],[Attrition_Risk_Percentage]] >= 0.75, "Critical",tbl_HR_Data[ [#This Row],[Attrition_Risk_Percentage] ]>= 0.5, "High",tbl_HR_Data[[#This Row],[Attrition_Risk_Percentage]] >= 0.25, "Medium",TRUE, "Low")} -> High | AR8: {=IFERROR(_xlfn.IFS(tbl_HR_Data[[#This Row],[Risk_Category]]="Critical",tbl_HR_Data[[#This Row],[MonthlyIncome]]*1.5,tbl_HR_Data[[#This Row],[Risk_Category]]="High",tbl_HR_Data[[#This Row],[MonthlyIncome]]*1.5),0)} -> 4005
A9: EMP-101094 | B9: 30 | C9: Travel_Rarely | D9: 1358 | E9: Research & Development | F9: 24 | G9: 1 | H9: Life Sciences | I9: 4 | J9: Male | K9: 67 | L9: 3 | M9: 1 | N9: Laboratory Technician | O9: 3 | P9: Divorced | Q9: 2693 | R9: 13335 | S9: 1 | T9: 0 | U9: 0.22 | V9: 4 | W9: 2 | X9: 1 | Y9: 1 | Z9: 2 | AA9: 3 | AB9: 1 | AC9: 0 | AD9: 0 | AE9: 0 | AF9: 0 | AG9: =IF(tbl_HR_Data[[#This Row],[Gender]]="Male",1,0) -> 1 | AH9: {=_xlfn.SWITCH(tbl_HR_Data[[#This Row],[BusinessTravel]], "Non-Travel", 0, "Travel_Rarely", 1, "Travel_Frequently", 2)} -> 1 | AI9: {=_xlfn.SWITCH(tbl_HR_Data[[#This Row],[MaritalStatus]],"Single",0,"Married",1,"Divorced",2)} -> 2 | AJ9: =IF(tbl_HR_Data[[#This Row],[OverTime]]=1,1,0) -> 0 | AK9: =IF(tbl_HR_Data[[#This Row],[DistanceFromHome]]>15,1,0) -> 1 | AL9: =IF(tbl_HR_Data[[#This Row],[JobSatisfaction]]<=2,1,0) -> 0 | AM9: =IF(tbl_HR_Data[[#This Row],[MonthlyIncome]]<$AT$2,1,0) -> 1 | AN9: =IF(tbl_HR_Data[[#This Row],[Travel_Code]]=2,1,0) -> 0 | AO9: =(tbl_HR_Data[[#This Row],[Flag_OT]] * Logic_Parameters!$B$2) + (tbl_HR_Data[[#This Row],[Flag_Travel]] * Logic_Parameters!$B$3) + (tbl_HR_Data[[#This Row],[Flag_Satisfaction]] * Logic_Parameters!$B$4) + (tbl_HR_Data[[#This Row],[Flag_Distance]]* Logic_Parameters!$B$5) + (tbl_HR_Data[[#This Row],[Flag_Income]] * Logic_Parameters!$B$6) -> 9.6605356 | AP9: =tbl_HR_Data[[#This Row],[Risk_Score_Raw]] / SUM(Logic_Parameters!$B$2:$B$6) -> 0.33282973 | AQ9: {=_xlfn.IFS(tbl_HR_Data[[#This Row],[Attrition_Risk_Percentage]] >= 0.75, "Critical",tbl_HR_Data[ [#This Row],[Attrition_Risk_Percentage] ]>= 0.5, "High",tbl_HR_Data[[#This Row],[Attrition_Risk_Percentage]] >= 0.25, "Medium",TRUE, "Low")} -> Medium | AR9: {=IFERROR(_xlfn.IFS(tbl_HR_Data[[#This Row],[Risk_Category]]="Critical",tbl_HR_Data[[#This Row],[MonthlyIncome]]*1.5,tbl_HR_Data[[#This Row],[Risk_Category]]="High",tbl_HR_Data[[#This Row],[MonthlyIncome]]*1.5),0)} -> 0
A10: EMP-100598 | B10: 38 | C10: Travel_Frequently | D10: 216 | E10: Research & Development | F10: 23 | G10: 3 | H10: Life Sciences | I10: 4 | J10: Male | K10: 44 | L10: 2 | M10: 3 | N10: Manufacturing Director | O10: 3 | P10: Single | Q10: 9526 | R10: 8787 | S10: 0 | T10: 0 | U10: 0.21 | V10: 4 | W10: 2 | X10: 0 | Y10: 10 | Z10: 2 | AA10: 3 | AB10: 9 | AC10: 7 | AD10: 1 | AE10: 8 | AF10: 0 | AG10: =IF(tbl_HR_Data[[#This Row],[Gender]]="Male",1,0) -> 1 | AH10: {=_xlfn.SWITCH(tbl_HR_Data[[#This Row],[BusinessTravel]], "Non-Travel", 0, "Travel_Rarely", 1, "Travel_Frequently", 2)} -> 2 | AI10: {=_xlfn.SWITCH(tbl_HR_Data[[#This Row],[MaritalStatus]],"Single",0,"Married",1,"Divorced",2)} -> 0 | AJ10: =IF(tbl_HR_Data[[#This Row],[OverTime]]=1,1,0) -> 0 | AK10: =IF(tbl_HR_Data[[#This Row],[DistanceFromHome]]>15,1,0) -> 1 | AL10: =IF(tbl_HR_Data[[#This Row],[JobSatisfaction]]<=2,1,0) -> 0 | AM10: =IF(tbl_HR_Data[[#This Row],[MonthlyIncome]]<$AT$2,1,0) -> 0 | AN10: =IF(tbl_HR_Data[[#This Row],[Travel_Code]]=2,1,0) -> 1 | AO10: =(tbl_HR_Data[[#This Row],[Flag_OT]] * Logic_Parameters!$B$2) + (tbl_HR_Data[[#This Row],[Flag_Travel]] * Logic_Parameters!$B$3) + (tbl_HR_Data[[#This Row],[Flag_Satisfaction]] * Logic_Parameters!$B$4) + (tbl_HR_Data[[#This Row],[Flag_Distance]]* Logic_Parameters!$B$5) + (tbl_HR_Data[[#This Row],[Flag_Income]] * Logic_Parameters!$B$6) -> 8.3264967 | AP10: =tbl_HR_Data[[#This Row],[Risk_Score_Raw]] / SUM(Logic_Parameters!$B$2:$B$6) -> 0.28686874 | AQ10: {=_xlfn.IFS(tbl_HR_Data[[#This Row],[Attrition_Risk_Percentage]] >= 0.75, "Critical",tbl_HR_Data[ [#This Row],[Attrition_Risk_Percentage] ]>= 0.5, "High",tbl_HR_Data[[#This Row],[Attrition_Risk_Percentage]] >= 0.25, "Medium",TRUE, "Low")} -> Medium | AR10: {=IFERROR(_xlfn.IFS(tbl_HR_Data[[#This Row],[Risk_Category]]="Critical",tbl_HR_Data[[#This Row],[MonthlyIncome]]*1.5,tbl_HR_Data[[#This Row],[Risk_Category]]="High",tbl_HR_Data[[#This Row],[MonthlyIncome]]*1.5),0)} -> 0
A11: EMP-100494 | B11: 36 | C11: Travel_Rarely | D11: 1299 | E11: Research & Development | F11: 27 | G11: 3 | H11: Medical | I11: 3 | J11: Male | K11: 94 | L11: 3 | M11: 2 | N11: Healthcare Representative | O11: 3 | P11: Married | Q11: 5237 | R11: 16577 | S11: 6 | T11: 0 | U11: 0.13 | V11: 3 | W11: 2 | X11: 2 | Y11: 17 | Z11: 3 | AA11: 2 | AB11: 7 | AC11: 7 | AD11: 7 | AE11: 7 | AF11: 0 | AG11: =IF(tbl_HR_Data[[#This Row],[Gender]]="Male",1,0) -> 1 | AH11: {=_xlfn.SWITCH(tbl_HR_Data[[#This Row],[BusinessTravel]], "Non-Travel", 0, "Travel_Rarely", 1, "Travel_Frequently", 2)} -> 1 | AI11: {=_xlfn.SWITCH(tbl_HR_Data[[#This Row],[MaritalStatus]],"Single",0,"Married",1,"Divorced",2)} -> 1 | AJ11: =IF(tbl_HR_Data[[#This Row],[OverTime]]=1,1,0) -> 0 | AK11: =IF(tbl_HR_Data[[#This Row],[DistanceFromHome]]>15,1,0) -> 1 | AL11: =IF(tbl_HR_Data[[#This Row],[JobSatisfaction]]<=2,1,0) -> 0 | AM11: =IF(tbl_HR_Data[[#This Row],[MonthlyIncome]]<$AT$2,1,0) -> 0 | AN11: =IF(tbl_HR_Data[[#This Row],[Travel_Code]]=2,1,0) -> 0 | AO11: =(tbl_HR_Data[[#This Row],[Flag_OT]] * Logic_Parameters!$B$2) + (tbl_HR_Data[[#This Row],[Flag_Travel]] * Logic_Parameters!$B$3) + (tbl_HR_Data[[#This Row],[Flag_Satisfaction]] * Logic_Parameters!$B$4) + (tbl_HR_Data[[#This Row],[Flag_Distance]]* Logic_Parameters!$B$5) + (tbl_HR_Data[[#This Row],[Flag_Income]] * Logic_Parameters!$B$6) -> 3.1661067 | AP11: =tbl_HR_Data[[#This Row],[Risk_Score_Raw]] / SUM(Logic_Parameters!$B$2:$B$6) -> 0.10908033 | AQ11: {=_xlfn.IFS(tbl_HR_Data[[#This Row],[Attrition_Risk_Percentage]] >= 0.75, "Critical",tbl_HR_Data[ [#This Row],[Attrition_Risk_Percentage] ]>= 0.5, "High",tbl_HR_Data[[#This Row],[Attrition_Risk_Percentage]] >= 0.25, "Medium",TRUE, "Low")} -> Low | AR11: {=IFERROR(_xlfn.IFS(tbl_HR_Data[[#This Row],[Risk_Category]]="Critical",tbl_HR_Data[[#This Row],[MonthlyIncome]]*1.5,tbl_HR_Data[[#This Row],[Risk_Category]]="High",tbl_HR_Data[[#This Row],[MonthlyIncome]]*1.5),0)} -> 0
A12: EMP-100740 | B12: 35 | C12: Travel_Rarely | D12: 809 | E12: Research & Development | F12: 16 | G12: 3 | H12: Medical | I12: 1 | J12: Male | K12: 84 | L12: 4 | M12: 1 | N12: Laboratory Technician | O12: 2 | P12: Married | Q12: 2426 | R12: 16479 | S12: 0 | T12: 0 | U12: 0.13 | V12: 3 | W12: 3 | X12: 1 | Y12: 6 | Z12: 5 | AA12: 3 | AB12: 5 | AC12: 4 | AD12: 0 | AE12: 3 | AF12: 0 | AG12: =IF(tbl_HR_Data[[#This Row],[Gender]]="Male",1,0) -> 1 | AH12: {=_xlfn.SWITCH(tbl_HR_Data[[#This Row],[BusinessTravel]], "Non-Travel", 0, "Travel_Rarely", 1, "Travel_Frequently", 2)} -> 1 | AI12: {=_xlfn.SWITCH(tbl_HR_Data[[#This Row],[MaritalStatus]],"Single",0,"Married",1,"Divorced",2)} -> 1 | AJ12: =IF(tbl_HR_Data[[#This Row],[OverTime]]=1,1,0) -> 0 | AK12: =IF(tbl_HR_Data[[#This Row],[DistanceFromHome]]>15,1,0) -> 1 | AL12: =IF(tbl_HR_Data[[#This Row],[JobSatisfaction]]<=2,1,0) -> 1 | AM12: =IF(tbl_HR_Data[[#This Row],[MonthlyIncome]]<$AT$2,1,0) -> 1 | AN12: =IF(tbl_HR_Data[[#This Row],[Travel_Code]]=2,1,0) -> 0 | AO12: =(tbl_HR_Data[[#This Row],[Flag_OT]] * Logic_Parameters!$B$2) + (tbl_HR_Data[[#This Row],[Flag_Travel]] * Logic_Parameters!$B$3) + (tbl_HR_Data[[#This Row],[Flag_Satisfaction]] * Logic_Parameters!$B$4) + (tbl_HR_Data[[#This Row],[Flag_Distance]]* Logic_Parameters!$B$5) + (tbl_HR_Data[[#This Row],[Flag_Income]] * Logic_Parameters!$B$6) -> 13.865069 | AP12: =tbl_HR_Data[[#This Row],[Risk_Score_Raw]] / SUM(Logic_Parameters!$B$2:$B$6) -> 0.47768646 | AQ12: {=_xlfn.IFS(tbl_HR_Data[[#This Row],[Attrition_Risk_Percentage]] >= 0.75, "Critical",tbl_HR_Data[ [#This Row],[Attrition_Risk_Percentage] ]>= 0.5, "High",tbl_HR_Data[[#This Row],[Attrition_Risk_Percentage]] >= 0.25, "Medium",TRUE, "Low")} -> Medium | AR12: {=IFERROR(_xlfn.IFS(tbl_HR_Data[[#This Row],[Risk_Category]]="Critical",tbl_HR_Data[[#This Row],[MonthlyIncome]]*1.5,tbl_HR_Data[[#This Row],[Risk_Category]]="High",tbl_HR_Data[[#This Row],[MonthlyIncome]]*1.5),0)} -> 0
A13: EMP-100694 | B13: 29 | C13: Travel_Rarely | D13: 153 | E13: Research & Development | F13: 15 | G13: 2 | H13: Life Sciences | I13: 4 | J13: Female | K13: 49 | L13: 2 | M13: 2 | N13: Laboratory Technician | O13: 3 | P13: Single | Q13: 4193 | R13: 12682 | S13: 0 | T13: 1 | U13: 0.12 | V13: 3 | W13: 4 | X13: 0 | Y13: 10 | Z13: 3 | AA13: 3 | AB13: 9 | AC13: 5 | AD13: 0 | AE13: 8 | AF13: 0 | AG13: =IF(tbl_HR_Data[[#This Row],[Gender]]="Male",1,0) -> 0 | AH13: {=_xlfn.SWITCH(tbl_HR_Data[[#This Row],[BusinessTravel]], "Non-Travel", 0, "Travel_Rarely", 1, "Travel_Frequently", 2)} -> 1 | AI13: {=_xlfn.SWITCH(tbl_HR_Data[[#This Row],[MaritalStatus]],"Single",0,"Married",1,"Divorced",2)} -> 0 | AJ13: =IF(tbl_HR_Data[[#This Row],[OverTime]]=1,1,0) -> 1 | AK13: =IF(tbl_HR_Data[[#This Row],[DistanceFromHome]]>15,1,0) -> 0 | AL13: =IF(tbl_HR_Data[[#This Row],[JobSatisfaction]]<=2,1,0) -> 0 | AM13: =IF(tbl_HR_Data[[#This Row],[MonthlyIncome]]<$AT$2,1,0) -> 1 | AN13: =IF(tbl_HR_Data[[#This Row],[Travel_Code]]=2,1,0) -> 0 | AO13: =(tbl_HR_Data[[#This Row],[Flag_OT]] * Logic_Parameters!$B$2) + (tbl_HR_Data[[#This Row],[Flag_Travel]] * Logic_Parameters!$B$3) + (tbl_HR_Data[[#This Row],[Flag_Satisfaction]] * Logic_Parameters!$B$4) + (tbl_HR_Data[[#This Row],[Flag_Distance]]* Logic_Parameters!$B$5) + (tbl_HR_Data[[#This Row],[Flag_Income]] * Logic_Parameters!$B$6) -> 16.494429 | AP13: =tbl_HR_Data[[#This Row],[Risk_Score_Raw]] / SUM(Logic_Parameters!$B$2:$B$6) -> 0.56827453 | AQ13: {=_xlfn.IFS(tbl_HR_Data[[#This Row],[Attrition_Risk_Percentage]] >= 0.75, "Critical",tbl_HR_Data[ [#This Row],[Attrition_Risk_Percentage] ]>= 0.5, "High",tbl_HR_Data[[#This Row],[Attrition_Risk_Percentage]] >= 0.25, "Medium",TRUE, "Low")} -> High | AR13: {=IFERROR(_xlfn.IFS(tbl_HR_Data[[#This Row],[Risk_Category]]="Critical",tbl_HR_Data[[#This Row],[MonthlyIncome]]*1.5,tbl_HR_Data[[#This Row],[Risk_Category]]="High",tbl_HR_Data[[#This Row],[MonthlyIncome]]*1.5),0)} -> 6289.5
A14: EMP-100043 | B14: 31 | C14: Travel_Rarely | D14: 670 | E14: Research & Development | F14: 26 | G14: 1 | H14: Life Sciences | I14: 1 | J14: Male | K14: 31 | L14: 3 | M14: 1 | N14: Research Scientist | O14: 3 | P14: Divorced | Q14: 2911 | R14: 15170 | S14: 1 | T14: 0 | U14: 0.17 | V14: 3 | W14: 4 | X14: 1 | Y14: 5 | Z14: 1 | AA14: 2 | AB14: 5 | AC14: 2 | AD14: 4 | AE14: 3 | AF14: 0 | AG14: =IF(tbl_HR_Data[[#This Row],[Gender]]="Male",1,0) -> 1 | AH14: {=_xlfn.SWITCH(tbl_HR_Data[[#This Row],[BusinessTravel]], "Non-Travel", 0, "Travel_Rarely", 1, "Travel_Frequently", 2)} -> 1 | AI14: {=_xlfn.SWITCH(tbl_HR_Data[[#This Row],[MaritalStatus]],"Single",0,"Married",1,"Divorced",2)} -> 2 | AJ14: =IF(tbl_HR_Data[[#This Row],[OverTime]]=1,1,0) -> 0 | AK14: =IF(tbl_HR_Data[[#This Row],[DistanceFromHome]]>15,1,0) -> 1 | AL14: =IF(tbl_HR_Data[[#This Row],[JobSatisfaction]]<=2,1,0) -> 0 | AM14: =IF(tbl_HR_Data[[#This Row],[MonthlyIncome]]<$AT$2,1,0) -> 1 | AN14: =IF(tbl_HR_Data[[#This Row],[Travel_Code]]=2,1,0) -> 0 | AO14: =(tbl_HR_Data[[#This Row],[Flag_OT]] * Logic_Parameters!$B$2) + (tbl_HR_Data[[#This Row],[Flag_Travel]] * Logic_Parameters!$B$3) + (tbl_HR_Data[[#This Row],[Flag_Satisfaction]] * Logic_Parameters!$B$4) + (tbl_HR_Data[[#This Row],[Flag_Distance]]* Logic_Parameters!$B$5) + (tbl_HR_Data[[#This Row],[Flag_Income]] * Logic_Parameters!$B$6) -> 9.6605356 | AP14: =tbl_HR_Data[[#This Row],[Risk_Score_Raw]] / SUM(Logic_Parameters!$B$2:$B$6) -> 0.33282973 | AQ14: {=_xlfn.IFS(tbl_HR_Data[[#This Row],[Attrition_Risk_Percentage]] >= 0.75, "Critical",tbl_HR_Data[ [#This Row],[Attrition_Risk_Percentage] ]>= 0.5, "High",tbl_HR_Data[[#This Row],[Attrition_Risk_Percentage]] >= 0.25, "Medium",TRUE, "Low")} -> Medium | AR14: {=IFERROR(_xlfn.IFS(tbl_HR_Data[[#This Row],[Risk_Category]]="Critical",tbl_HR_Data[[#This Row],[MonthlyIncome]]*1.5,tbl_HR_Data[[#This Row],[Risk_Category]]="High",tbl_HR_Data[[#This Row],[MonthlyIncome]]*1.5),0)} -> 0
... A1471: EMP-100596 | B1471: 34 | C1471: Travel_Rarely | D1471: 628 | E1471: Research & Development | F1471: 8 | G1471: 3 | H1471: Medical | I1471: 2 | J1471: Male | K1471: 82 | L1471: 4 | M1471: 2 | N1471: Laboratory Technician | O1471: 3 | P1471: Married | Q1471: 4404 | R1471: 10228 | S1471: 2 | T1471: 0 | U1471: 0.12 | V1471: 3 | W1471: 1 | X1471: 0 | Y1471: 6 | Z1471: 3 | AA1471: 4 | AB1471: 4 | AC1471: 3 | AD1471: 1 | AE1471: 2 | AF1471: 0 | AG1471: =IF(tbl_HR_Data[[#This Row],[Gender]]="Male",1,0) -> 1 | AH1471: {=_xlfn.SWITCH(tbl_HR_Data[[#This Row],[BusinessTravel]], "Non-Travel", 0, "Travel_Rarely", 1, "Travel_Frequently", 2)} -> 1 | AI1471: {=_xlfn.SWITCH(tbl_HR_Data[[#This Row],[MaritalStatus]],"Single",0,"Married",1,"Divorced",2)} -> 1 | AJ1471: =IF(tbl_HR_Data[[#This Row],[OverTime]]=1,1,0) -> 0 | AK1471: =IF(tbl_HR_Data[[#This Row],[DistanceFromHome]]>15,1,0) -> 0 | AL1471: =IF(tbl_HR_Data[[#This Row],[JobSatisfaction]]<=2,1,0) -> 0 | AM1471: =IF(tbl_HR_Data[[#This Row],[MonthlyIncome]]<$AT$2,1,0) -> 1 | AN1471: =IF(tbl_HR_Data[[#This Row],[Travel_Code]]=2,1,0) -> 0 | AO1471: =(tbl_HR_Data[[#This Row],[Flag_OT]] * Logic_Parameters!$B$2) + (tbl_HR_Data[[#This Row],[Flag_Travel]] * Logic_Parameters!$B$3) + (tbl_HR_Data[[#This Row],[Flag_Satisfaction]] * Logic_Parameters!$B$4) + (tbl_HR_Data[[#This Row],[Flag_Distance]]* Logic_Parameters!$B$5) + (tbl_HR_Data[[#This Row],[Flag_Income]] * Logic_Parameters!$B$6) -> 6.4944289 | AP1471: =tbl_HR_Data[[#This Row],[Risk_Score_Raw]] / SUM(Logic_Parameters!$B$2:$B$6) -> 0.2237494 | AQ1471: {=_xlfn.IFS(tbl_HR_Data[[#This Row],[Attrition_Risk_Percentage]] >= 0.75, "Critical",tbl_HR_Data[ [#This Row],[Attrition_Risk_Percentage] ]>= 0.5, "High",tbl_HR_Data[[#This Row],[Attrition_Risk_Percentage]] >= 0.25, "Medium",TRUE, "Low")} -> Low | AR1471: {=IFERROR(_xlfn.IFS(tbl_HR_Data[[#This Row],[Risk_Category]]="Critical",tbl_HR_Data[[#This Row],[MonthlyIncome]]*1.5,tbl_HR_Data[[#This Row],[Risk_Category]]="High",tbl_HR_Data[[#This Row],[MonthlyIncome]]*1.5),0)} -> 0

Sheet Logic_Parameters
A1: Factor | B1: Weight (1-10) | C1: Description | E1: Factor | F1: Raw Correlation | G1: Strength (Absolute) | H1: Final Weight (1-10)
A2: Overtime | B2: =tbl_correl[[#This Row],[Final Weight (1-10)]] -> 10 | C2: Highest impact on attrition | E2: OverTime | F2: =CORREL(tbl_HR_Data[Attrition],tbl_HR_Data[OverTime]) -> 0.24611799 | G2: =ABS(tbl_correl[[#This Row],[Raw Correlation]]) -> 0.24611799 | H2: =(tbl_correl[[#This Row],[Strength (Absolute)]]/MAX(tbl_correl[Strength (Absolute)]))*10 -> 10
A3: Travel Frequency | B3: =tbl_correl[[#This Row],[Final Weight (1-10)]] -> 5.16039 | C3: High travel = higher risk | E3: Travel_Code | F3: =CORREL(tbl_HR_Data[Attrition],tbl_HR_Data[Travel_Code]) -> 0.12700648 | G3: =ABS(tbl_correl[[#This Row],[Raw Correlation]]) -> 0.12700648 | H3: =(tbl_correl[[#This Row],[Strength (Absolute)]]/MAX(tbl_correl[Strength (Absolute)]))*10 -> 5.16039
A4: Low Job Satisfaction | B4: =tbl_correl[[#This Row],[Final Weight (1-10)]] -> 4.2045331 | C4: Disengaged employees leave faster | E4: JobSatisfaction | F4: =CORREL(tbl_HR_Data[Attrition],tbl_HR_Data[JobSatisfaction]) -> -0.10348113 | G4: =ABS(tbl_correl[[#This Row],[Raw Correlation]]) -> 0.10348113 | H4: =(tbl_correl[[#This Row],[Strength (Absolute)]]/MAX(tbl_correl[Strength (Absolute)]))*10 -> 4.2045331
A5: Distance From Home | B5: =tbl_correl[[#This Row],[Final Weight (1-10)]] -> 3.1661067 | C5: Long commutes contribute to burnout | E5: DistanceFromHome | F5: =CORREL(tbl_HR_Data[Attrition],tbl_HR_Data[DistanceFromHome]) -> 0.077923583 | G5: =ABS(tbl_correl[[#This Row],[Raw Correlation]]) -> 0.077923583 | H5: =(tbl_correl[[#This Row],[Strength (Absolute)]]/MAX(tbl_correl[Strength (Absolute)]))*10 -> 3.1661067
A6: Low Monthly Income | B6: =tbl_correl[[#This Row],[Final Weight (1-10)]] -> 6.4944289 | C6: Compensation is a key driver | E6: MonthlyIncome | F6: =CORREL(tbl_HR_Data[Attrition],tbl_HR_Data[MonthlyIncome]) -> -0.15983958 | G6: =ABS(tbl_correl[[#This Row],[Raw Correlation]]) -> 0.15983958 | H6: =(tbl_correl[[#This Row],[Strength (Absolute)]]/MAX(tbl_correl[Strength (Absolute)]))*10 -> 6.4944289

Sheet Pivot_Engine
A1: Count of EmployeeID | B1: Average of Attrition | C1: Average of Attrition_Risk_Percentage | E1: Department_Role | F1: Sum of Attrition | I1: Risk Category | J1: Count of EmployeeID | K1: Sum of Attrition | M1: Average of Attrition_Risk_Percentage
A2: 1470 | B2: 0.16122449 | C2: 0.3233582 | E2: Research & Development | F2: 133 | I2: Critical | J2: 40 | K2: 26 | M2: Overtime | N2: Non-Travel | O2: Travel_Frequently | P2: Travel_Rarely | Q2: Grand Total
E3: Laboratory Technician | F3: 62 | I3: High | J3: 276 | K3: 88 | M3: 0 | N3: 0.19178541 | O3: 0.37387198 | P3: 0.19369233 | Q3: 0.22613542
E4: Research Scientist | F4: 47 | I4: Medium | J4: 516 | K4: 79 | M4: 1 | N4: 0.52420561 | O4: 0.71622837 | P4: 0.53236269 | Q4: 0.56968709
E5: Manufacturing Director | F5: 10 | I5: Low | J5: 638 | K5: 44 | M5: Grand Total | N5: 0.26935012 | O5: 0.48016313 | P5: 0.28948117 | Q5: 0.3233582
A6: Age Group | B6: Average of Attrition_Risk_Percentage | E6: Healthcare Representative | F6: 9 | I6: Grand Total | J6: 1470 | K6: 237
A7: 0-4 | B7: 0.37625556 | E7: Manager | F7: 3
A8: 30-34 | B8: 0.31857096 | E8: Research Director | F8: 2 | I8: Critical | J8: =IFERROR(GETPIVOTDATA("Sum of Attrition",$I$1,"Risk_Category","Critical"),0) -> 26 | N8: Column Labels
A9: 5-9 | B9: 0.30960816 | E9: Sales | F9: 92 | I9: High | J9: =IFERROR(GETPIVOTDATA("Sum of Attrition",$I$1,"Risk_Category","High"),0) -> 88 | N9: Count of EmployeeID | Q9: Average of Attrition_Risk_Percentage | T9: Total Count of EmployeeID | U9: Total Average of Attrition_Risk_Percentage
A10: 15-19 | B10: 0.27515335 | E10: Sales Executive | F10: 57 | I10: Medium | J10: =IFERROR(GETPIVOTDATA("Sum of Attrition",$I$1,"Risk_Category","Medium"),0) -> 79 | M10: Row Labels | N10: Human Resources | O10: Research & Development | P10: Sales | Q10: Human Resources | R10: Research & Development | S10: Sales
A11: 10-14 | B11: 0.26251212 | E11: Sales Representative | F11: 33 | I11: Low | J11: =IFERROR(GETPIVOTDATA("Sum of Attrition",$I$1,"Risk_Category","Low"),0) -> 44 | M11: 18-27 | N11: 0.12698413 | O11: 0.14255983 | P11: 0.14573991 | Q11: 0.49904782 | R11: 0.41235323 | S11: 0.40232591 | T11: 0.14285714 | U11: 0.41255219
A12: 25-29 | B12: 0.24715293 | E12: Manager | F12: 2 | M12: 28-37 | N12: 0.38095238 | O12: 0.42663892 | P12: 0.4573991 | Q12: 0.38021885 | R12: 0.35128712 | S12: 0.27854441 | T12: 0.43401361 | U12: 0.32911603
A13: 20-24 | B13: 0.22767768 | E13: Human Resources | F13: 12 | I13: Active category: | J13: =COUNTIF(J8:J11,">0") -> 4 | M13: 38-47 | N13: 0.36507937 | O13: 0.27471384 | P13: 0.26681614 | Q13: 0.26335823 | R13: 0.31563183 | S13: 0.26699444 | T13: 0.27619048 | U13: 0.29841473
A14: 35-40 | B14: 0.17688563 | E14: Human Resources | F14: 12 | M14: 48-57 | N14: 0.095238095 | O14: 0.1383975 | P14: 0.10762332 | Q14: 0.37714808 | R14: 0.25749994 | S14: 0.24884581 | T14: 0.12721088 | U14: 0.25911754
A15: Grand Total | B15: 0.3233582 | E15: Manager | F15: 0 | I15: Logic for Donut Scorecard | J15: =IF(J13=1, IF(J8>0,J8&CHAR(10)&"Critical Risk", IF(J9>0,J9&CHAR(10)&"High Risk", IF(J10>0,J10&CHAR(10)&"Medium Risk", IF(J11>0,J11&CHAR(10)&"Low Risk","")))), (J8+J9)&CHAR(10)&"Total At-Risk" ) -> 114 Total At-Risk | M15: 58-67 | N15: 0.031746032 | O15: 0.017689906 | P15: 0.022421525 | Q15: 0.1118747 | R15: 0.38144486 | S15: 0.24049005 | T15: 0.019727891 | U15: 0.31424871
E16: Grand Total | F16: 237 | J16: =IF(J13=1, IF(J8>0,J8&CHAR(10)&"Critical Risk", IF(J9>0,J9&CHAR(10)&"High Risk", IF(J10>0,J10&CHAR(10)&"Medium Risk", IF(J11>0,J11&CHAR(10)&"Low Risk","")))), IF((J8+J9)>0, (J8+J9)&CHAR(10)&"Total At-Risk", (J10+J11)&CHAR(10)&"Not At-Risk" ) ) -> 114 Total At-Risk | M16: Grand Total | N16: 1 | O16: 1 | P16: 1 | Q16: 0.34383352 | R16: 0.33775127 | S16: 0.2894531 | T16: 1 | U16: 0.3233582
E20: Income Group | F20: Average of Attrition_Risk_Percentage | I20: Average of Attrition_Risk_Percentage | J20: Column Labels
A21: Education Field | B21: Count of EmployeeID | C21: Average of Attrition_Risk_Percentage | E21: 1000-3499 | F21: 0.43351002 | I21: Row Labels | J21: Divorced | K21: Married | L21: Single | M21: Grand Total
A22: Human Resources | B22: 27 | C22: 0.35695923 | E22: 3500-5999 | F22: 0.34933705 | I22: Female | J22: 0.35693972 | K22: 0.3056102 | L22: 0.35222735 | M22: 0.33160062
A23: Life Sciences | B23: 606 | C23: 0.31798874 | E23: 6000-8499 | F23: 0.19976634 | I23: Male | J23: 0.3045253 | K23: 0.32228656 | L23: 0.32165377 | M23: 0.31786326
A24: Marketing | B24: 159 | C24: 0.29500716 | E24: 8500-10999 | F24: 0.21801346 | I24: Grand Total | J24: 0.32327908 | K24: 0.31554663 | L24: 0.33459876 | M24: 0.3233582
A25: Medical | B25: 464 | C25: 0.33037501 | E25: 11000-13499 | F25: 0.24697568
A26: Other | B26: 82 | C26: 0.35943971 | E26: 13500-15999 | F26: 0.24931849
A27: Technical Degree | B27: 132 | C27: 0.32820674 | E27: 16000-18499 | F27: 0.19587376
A28: Grand Total | B28: 1470 | C28: 0.3233582 | E28: 18500-20999 | F28: 0.17578045
E29: Grand Total | F29: 0.3233582
I30: Attrition | J30: 0
I31: Risk_Category | J31: (All)
I33: Employee ID | J33: Job Role | K33: Risk (%) | L33: Performance Rating
A34: Row Labels | B34: Count of EmployeeID | C34: Sum of Attrition | D34: Average of Attrition | E34: Average of MonthlyIncome | I34: EMP-100258 | J34: Research Scientist | K34: 0.85514327 | L34: 3
A35: Female | B35: 588 | C35: 87 | D35: 0.14795918 | E35: 6686.5663 | I35: EMP-100284 | J35: Laboratory Technician | K35: 0.8222116 | L35: 3
A36: Male | B36: 882 | C36: 150 | D36: 0.17006803 | E36: 6380.5079 | I36: EMP-100363 | J36: Research Scientist | K36: 0.8222116 | L36: 3
A37: Grand Total | B37: 1470 | C37: 237 | D37: 0.16122449 | E37: 6502.9313 | I37: EMP-100462 | J37: Manufacturing Director | K37: 0.8222116 | L37: 3
I38: EMP-100673 | J38: Healthcare Representative | K38: 0.89091967 | L38: 3
I39: EMP-100713 | J39: Research Scientist | K39: 0.8222116 | L39: 3
I40: EMP-100760 | J40: Laboratory Technician | K40: 0.8222116 | L40: 3
I41: EMP-100771 | J41: Research Scientist | K41: 0.89091967 | L41: 3
I42: EMP-100846 | J42: Human Resources | K42: 0.89091967 | L42: 3
I43: EMP-101057 | J43: Research Scientist | K43: 0.89091967 | L43: 3
I44: EMP-101203 | J44: Laboratory Technician | K44: 0.8222116 | L44: 3
...

Sheet Documentation
A1: Project Documentation: HR Predictive Attrition Dashboard
A3: 1. Project Objective
A5: To transition from descriptive HR reporting to Predictive Workforce Analytics. This tool identifies high-risk employees by quantifying qualitative and quantitative "attrition drivers" into a single Predictive Risk Score.
A7: 2. The ETL Process (Extract, Transform, Load)
A9: The raw data was transformed into a structured "Logic Layer" using the following steps:
A11: Table Conversion: Raw data converted to tbl_HR_Data for dynamic formula range expansion.
A13: Categorical Encoding: Text values were mapped to integers (e.g., Travel_Frequently = 2) to allow for mathematical correlation.
A15: Data Cleaning: Applied TRIM and standardized naming conventions to ensure Pivot Table accuracy.
A17: 3. The Predictive Engine (Mathematical Logic)
A19: The Attrition Risk Score is calculated using a Weighted Factor Model based on statistical correlation.
A21: Risk Factors & Weights
A23: Overtime (Weight: 10.0): Identified as the #1 driver of attrition.
... A55: 3. Adjusting Logic: If business priorities change, update the "Weights" in the Logic_Parameters sheet. The entire dashboard will recalibrate automatically.
